Workbook

Sheet Summary
A1: MasterKraft — product data gaps
A2: Missing features, weights and carton dimensions. Generated 25 August 2026 from the committed catalogue snapshot.
A4: THE SET
A5: Products in this workbook (listable) | B5: =COUNTA(Products!A2:A284) | C5: Everything published in WooCommerce that is not hidden and not retired in Unleashed. 512 published products reduce to this.
A6: Of those, served to customers | B6: =COUNTIF(Products!D2:D284,"Yes") | C6: Passes the brand-SKU rules as well, so it is what actually appears on the site. Work on these first; the rest are not shown to anyone.
A8: GAPS, SERVED PRODUCTS ONLY
A9: Missing features | B9: =COUNTIFS(Products!D2:D284,"Yes",Products!F2:F284,"No") | C9: No feature bullets, so the product page shows none. Content job.
A10: Missing weight | B10: =COUNTIFS(Products!D2:D284,"Yes",Products!G2:G284,"") | C10: Blocks any automated freight quote.
A11: Missing dimensions | B11: =SUMPRODUCT((Products!D2:D284="Yes")*(((Products!H2:H284="")+(Products!I2:I284="")+(Products!J2:J284=""))>0)) | C11: Blocks any automated freight quote. Carton, not assembled size. Counts a product missing ANY of length, width or height - 28 carry only some of the three.
A12: Missing at least one of the three | B12: =COUNTIFS(Products!D2:D284,"Yes",Products!K2:K284,"?*") | C12: The real size of the job.
A14: FREIGHT IMPACT, SERVED PRODUCTS
A15: Quotable by Australia Post today | B15: =COUNTIFS(Products!D2:D284,"Yes",Products!L2:L284,"Yes") | C15: Within 22kg, 105cm longest side and 0.25 cubic metres.
A16: Too big for Australia Post | B16: =COUNTIFS(Products!D2:D284,"Yes",Products!L2:L284,"Too big") | C16: Racks, rigs, machines and benches. Pallet freight, and always were. Filling in data will not change these.
A17: Cannot be assessed, no data | B17: =COUNTIFS(Products!D2:D284,"Yes",Products!L2:L284,"No data") | C17: THIS is the number that filling in weights and dimensions moves.
A19: HOW TO USE THIS
A20: Each row is one product. Filter the Products tab on "Served = Yes" and "What is missing" not blank. Edit in WordPress: Products → the product → Inventory/Shipping for weight and dimensions, and the ACF features fields for feature bullets. Dimensions are the SHIPPING CARTON in centimetres, not the assembled size, and weight is the carton weight in kilograms. The two right-hand columns are formulas: they recalculate as you fill cells in, so this workbook can be used to track progress. Everything else is data as it stood when the file was generated.
A23: ONE PRODUCT NEEDS CORRECTING, NOT FILLING
A24: ABPBSB04 (Plyometric Foam Stacker Box - 12") is recorded as 850 x 1000 x 305 cm, which is 259 cubic metres. That is millimetres typed into a centimetre field. It is highlighted on the Products tab.

Sheet Products
A1: SKU | B1: Product | C1: Category | D1: Served | E1: Clearance | F1: Features | G1: Weight (kg) | H1: Length (cm) | I1: Width (cm) | J1: Height (cm) | K1: What is missing | L1: AusPost quotable | M1: Page
A2: ABCTDR01 | B2: Drop In Core Trainer | C2: Body Weight | D2: Yes | E2: Yes | F2: Yes | G2: 3 | H2: 43 | I2: 8 | J2: 8 | K2: =TRIM(IF(F2="No","Features ","")&IF(G2="","Weight ","")&IF(OR(H2="",I2="",J2="")," Dimensions","")) | L2: =IF(OR(G2="",H2="",I2="",J2=""),"No data",IF(AND(G2<=22,MAX(H2:J2)<=105,(H2*I2*J2)/1000000<=0.25),"Yes","Too big")) | M2: /product/drop-in-core-trainer
A3: ABCTFS02 | B3: Core Trainer (Landmine) With T Bar Handle | C3: Body Weight | D3: Yes | E3: Yes | F3: No | G3: 17 | H3: 42 | I3: 17 | J3: 59 | K3: =TRIM(IF(F3="No","Features ","")&IF(G3="","Weight ","")&IF(OR(H3="",I3="",J3="")," Dimensions","")) | L3: =IF(OR(G3="",H3="",I3="",J3=""),"No data",IF(AND(G3<=22,MAX(H3:J3)<=105,(H3*I3*J3)/1000000<=0.25),"Yes","Too big")) | M3: /product/core-trainer-landmine-with-t-bar-handle-2
A4: ABEMMA01 | B4: EVA Exercise Mat | C4: Body Weight | D4: Yes | E4: Yes | F4: No | G4: 3 | H4: 140 | I4: 62 | J4: 1.6 | K4: =TRIM(IF(F4="No","Features ","")&IF(G4="","Weight ","")&IF(OR(H4="",I4="",J4="")," Dimensions","")) | L4: =IF(OR(G4="",H4="",I4="",J4=""),"No data",IF(AND(G4<=22,MAX(H4:J4)<=105,(H4*I4*J4)/1000000<=0.25),"Yes","Too big")) | M4: /product/eva-exercise-mat
A5: ABPBMS-01-1 | B5: Plyometric Box 45cm | C5: Body Weight | D5: Yes | E5: Yes | F5: No | G5: 9 | H5: 44 | I5: 44 | J5: 47 | K5: =TRIM(IF(F5="No","Features ","")&IF(G5="","Weight ","")&IF(OR(H5="",I5="",J5="")," Dimensions","")) | L5: =IF(OR(G5="",H5="",I5="",J5=""),"No data",IF(AND(G5<=22,MAX(H5:J5)<=105,(H5*I5*J5)/1000000<=0.25),"Yes","Too big")) | M5: /product/plyometric-box-45cm
A6: ABPBSB-06 | B6: Plyometric Foam Stacker Box- 24" | C6: Body Weight | D6: Yes | E6: Yes | F6: Yes | G6: 13 | H6: 85 | I6: 100 | J6: 30.5 | K6: =TRIM(IF(F6="No","Features ","")&IF(G6="","Weight ","")&IF(OR(H6="",I6="",J6="")," Dimensions","")) | L6: =IF(OR(G6="",H6="",I6="",J6=""),"No data",IF(AND(G6<=22,MAX(H6:J6)<=105,(H6*I6*J6)/1000000<=0.25),"Yes","Too big")) | M6: /product/plyometric-foam-stacker-box-24
A7: ABPBSB04 | B7: Plyometric Foam Stacker Box- 12" | C7: Body Weight | D7: Yes | E7: Yes | F7: Yes | G7: 13 | H7: 850 | I7: 1000 | J7: 305 | K7: =TRIM(IF(F7="No","Features ","")&IF(G7="","Weight ","")&IF(OR(H7="",I7="",J7="")," Dimensions","")) | L7: =IF(OR(G7="",H7="",I7="",J7=""),"No data",IF(AND(G7<=22,MAX(H7:J7)<=105,(H7*I7*J7)/1000000<=0.25),"Yes","Too big")) | M7: /product/foam-plyometric-box-alt-v
A8: ABRPBA01 | B8: Knitted Resistance Bands (Set of 3) | C8: Body Weight | D8: Yes | E8: Yes | F8: No | G8: 1 | H8: 34 | I8: 24 | J8: 2 | K8: =TRIM(IF(F8="No","Features ","")&IF(G8="","Weight ","")&IF(OR(H8="",I8="",J8="")," Dimensions","")) | L8: =IF(OR(G8="",H8="",I8="",J8=""),"No data",IF(AND(G8<=22,MAX(H8:J8)<=105,(H8*I8*J8)/1000000<=0.25),"Yes","Too big")) | M8: /product/knitted-resistance-bands-set-of-3-2
A9: ABRPPO | B9: Power Bands | C9: Body Weight | D9: Yes | E9: Yes | F9: No | K9: =TRIM(IF(F9="No","Features ","")&IF(G9="","Weight ","")&IF(OR(H9="",I9="",J9="")," Dimensions","")) | L9: =IF(OR(G9="",H9="",I9="",J9=""),"No data",IF(AND(G9<=22,MAX(H9:J9)<=105,(H9*I9*J9)/1000000<=0.25),"Yes","Too big")) | M9: /product/power-bands-alt-v
A10: ABSADI01 | B10: Mini Disc Cones (Set of 50) | C10: Body Weight | D10: Yes | E10: Yes | F10: No | G10: 2 | H10: 15 | I10: 15 | J10: 15 | K10: =TRIM(IF(F10="No","Features ","")&IF(G10="","Weight ","")&IF(OR(H10="",I10="",J10="")," Dimensions","")) | L10: =IF(OR(G10="",H10="",I10="",J10=""),"No data",IF(AND(G10<=22,MAX(H10:J10)<=105,(H10*I10*J10)/1000000<=0.25),"Yes","Too big")) | M10: /product/mini-disc-cones-set-of-50-2
A11: ABSADO01 | B11: Station Markers (Set of 96) - Numbers | C11: Body Weight | D11: Yes | E11: Yes | F11: No | K11: =TRIM(IF(F11="No","Features ","")&IF(G11="","Weight ","")&IF(OR(H11="",I11="",J11="")," Dimensions","")) | L11: =IF(OR(G11="",H11="",I11="",J11=""),"No data",IF(AND(G11<=22,MAX(H11:J11)<=105,(H11*I11*J11)/1000000<=0.25),"Yes","Too big")) | M11: /product/station-markers-set-of-96-numbers
A12: ABSADO02 | B12: Station Markers (Set of 15) - Boost | C12: Body Weight | D12: Yes | E12: Yes | F12: No | K12: =TRIM(IF(F12="No","Features ","")&IF(G12="","Weight ","")&IF(OR(H12="",I12="",J12="")," Dimensions","")) | L12: =IF(OR(G12="",H12="",I12="",J12=""),"No data",IF(AND(G12<=22,MAX(H12:J12)<=105,(H12*I12*J12)/1000000<=0.25),"Yes","Too big")) | M12: /product/station-markers-set-of-15-boost
A13: ABSADO03 | B13: Station Markers (Set of 15) - Rep | C13: Body Weight | D13: Yes | E13: Yes | F13: No | K13: =TRIM(IF(F13="No","Features ","")&IF(G13="","Weight ","")&IF(OR(H13="",I13="",J13="")," Dimensions","")) | L13: =IF(OR(G13="",H13="",I13="",J13=""),"No data",IF(AND(G13<=22,MAX(H13:J13)<=105,(H13*I13*J13)/1000000<=0.25),"Yes","Too big")) | M13: /product/station-markers-set-of-15-rep
A14: ABSADO04 | B14: Station Markers (Set of 15) - Neural | C14: Body Weight | D14: Yes | E14: Yes | F14: No | K14: =TRIM(IF(F14="No","Features ","")&IF(G14="","Weight ","")&IF(OR(H14="",I14="",J14="")," Dimensions","")) | L14: =IF(OR(G14="",H14="",I14="",J14=""),"No data",IF(AND(G14<=22,MAX(H14:J14)<=105,(H14*I14*J14)/1000000<=0.25),"Yes","Too big")) | M14: /product/station-markers-set-of-15-neural
A15: ABSADO05 | B15: Station Markers (Set of 15) - Form | C15: Body Weight | D15: Yes | E15: Yes | F15: No | K15: =TRIM(IF(F15="No","Features ","")&IF(G15="","Weight ","")&IF(OR(H15="",I15="",J15="")," Dimensions","")) | L15: =IF(OR(G15="",H15="",I15="",J15=""),"No data",IF(AND(G15<=22,MAX(H15:J15)<=105,(H15*I15*J15)/1000000<=0.25),"Yes","Too big")) | M15: /product/station-markers-set-of-15-form
A16: ABSADO06 | B16: Station Markers (Set of 15) - Hero | C16: Body Weight | D16: Yes | E16: Yes | F16: No | K16: =TRIM(IF(F16="No","Features ","")&IF(G16="","Weight ","")&IF(OR(H16="",I16="",J16="")," Dimensions","")) | L16: =IF(OR(G16="",H16="",I16="",J16=""),"No data",IF(AND(G16<=22,MAX(H16:J16)<=105,(H16*I16*J16)/1000000<=0.25),"Yes","Too big")) | M16: /product/station-markers-set-of-15-hero
A17: ABSADO07 | B17: Station Markers (Set of 15) - Functional | C17: Body Weight | D17: Yes | E17: Yes | F17: No | K17: =TRIM(IF(F17="No","Features ","")&IF(G17="","Weight ","")&IF(OR(H17="",I17="",J17="")," Dimensions","")) | L17: =IF(OR(G17="",H17="",I17="",J17=""),"No data",IF(AND(G17<=22,MAX(H17:J17)<=105,(H17*I17*J17)/1000000<=0.25),"Yes","Too big")) | M17: /product/station-markers-set-of-15-functional
A18: ABSADO08 | B18: Station Markers (Set of 15) - Sherpa | C18: Body Weight | D18: Yes | E18: Yes | F18: No | K18: =TRIM(IF(F18="No","Features ","")&IF(G18="","Weight ","")&IF(OR(H18="",I18="",J18="")," Dimensions","")) | L18: =IF(OR(G18="",H18="",I18="",J18=""),"No data",IF(AND(G18<=22,MAX(H18:J18)<=105,(H18*I18*J18)/1000000<=0.25),"Yes","Too big")) | M18: /product/station-markers-set-of-15-sherpa
A19: ABSUTR01 | B19: Suspension Trainer | C19: Body Weight | D19: Yes | E19: Yes | F19: No | G19: 6 | H19: 23 | I19: 23 | J19: 9 | K19: =TRIM(IF(F19="No","Features ","")&IF(G19="","Weight ","")&IF(OR(H19="",I19="",J19="")," Dimensions","")) | L19: =IF(OR(G19="",H19="",I19="",J19=""),"No data",IF(AND(G19<=22,MAX(H19:J19)<=105,(H19*I19*J19)/1000000<=0.25),"Yes","Too big")) | M19: /product/suspension-trainer
A20: MBASADJ-GROUP | B20: Group Fitness Step | C20: Body Weight | D20: Yes | F20: Yes | G20: 18 | H20: 44.5 | I20: 44.5 | J20: 37 | K20: =TRIM(IF(F20="No","Features ","")&IF(G20="","Weight ","")&IF(OR(H20="",I20="",J20="")," Dimensions","")) | L20: =IF(OR(G20="",H20="",I20="",J20=""),"No data",IF(AND(G20<=22,MAX(H20:J20)<=105,(H20*I20*J20)/1000000<=0.25),"Yes","Too big")) | M20: /product/group-fitness-step
A21: MBASADJ01 | B21: Group Fitness Step (Adjustable) | C21: Body Weight | D21: Yes | F21: No | G21: 13 | H21: 120 | I21: 31 | J21: 20 | K21: =TRIM(IF(F21="No","Features ","")&IF(G21="","Weight ","")&IF(OR(H21="",I21="",J21="")," Dimensions","")) | L21: =IF(OR(G21="",H21="",I21="",J21=""),"No data",IF(AND(G21<=22,MAX(H21:J21)<=105,(H21*I21*J21)/1000000<=0.25),"Yes","Too big")) | M21: /product/group-fitness-step-adjustable
A22: MBBSCU01 | B22: Balance Cushion | C22: Body Weight | D22: Yes | F22: No | G22: 3 | H22: 33 | I22: 33 | J22: 6 | K22: =TRIM(IF(F22="No","Features ","")&IF(G22="","Weight ","")&IF(OR(H22="",I22="",J22="")," Dimensions","")) | L22: =IF(OR(G22="",H22="",I22="",J22=""),"No data",IF(AND(G22<=22,MAX(H22:J22)<=105,(H22*I22*J22)/1000000<=0.25),"Yes","Too big")) | M22: /product/balance-cushion
A23: MBBSTR01 | B23: Fitness &amp; Balance Trainer | C23: Body Weight | D23: Yes | F23: No | G23: 8 | H23: 6.6 | I23: 6.6 | J23: 0.9 | K23: =TRIM(IF(F23="No","Features ","")&IF(G23="","Weight ","")&IF(OR(H23="",I23="",J23="")," Dimensions","")) | L23: =IF(OR(G23="",H23="",I23="",J23=""),"No data",IF(AND(G23<=22,MAX(H23:J23)<=105,(H23*I23*J23)/1000000<=0.25),"Yes","Too big")) | M23: /product/fitness-balance-trainer
A24: MBCTACC01 | B24: Utility Roller | C24: Body Weight | D24: Yes | F24: Yes | G24: 10 | H24: 68 | I24: 34.5 | J24: 8.5 | K24: =TRIM(IF(F24="No","Features ","")&IF(G24="","Weight ","")&IF(OR(H24="",I24="",J24="")," Dimensions","")) | L24: =IF(OR(G24="",H24="",I24="",J24=""),"No data",IF(AND(G24<=22,MAX(H24:J24)<=105,(H24*I24*J24)/1000000<=0.25),"Yes","Too big")) | M24: /product/utility-roller
A25: MBCTDI01 | B25: Exercise Glider Discs (Pair) | C25: Body Weight | D25: Yes | F25: Yes | G25: 1 | H25: 20 | I25: 22 | J25: 10 | K25: =TRIM(IF(F25="No","Features ","")&IF(G25="","Weight ","")&IF(OR(H25="",I25="",J25="")," Dimensions","")) | L25: =IF(OR(G25="",H25="",I25="",J25=""),"No data",IF(AND(G25<=22,MAX(H25:J25)<=105,(H25*I25*J25)/1000000<=0.25),"Yes","Too big")) | M25: /product/exercise-glider-discs-pair
A26: MBCTDR01 | B26: Drop In Core Trainer | C26: Body Weight | D26: Yes | F26: No | G26: 3 | H26: 43 | I26: 8 | J26: 8 | K26: =TRIM(IF(F26="No","Features ","")&IF(G26="","Weight ","")&IF(OR(H26="",I26="",J26="")," Dimensions","")) | L26: =IF(OR(G26="",H26="",I26="",J26=""),"No data",IF(AND(G26<=22,MAX(H26:J26)<=105,(H26*I26*J26)/1000000<=0.25),"Yes","Too big")) | M26: /product/drop-in-core-trainer-2
A27: MBCTFS02 | B27: Core Trainer (Landmine) With T Bar Handle | C27: Body Weight | D27: Yes | F27: Yes | G27: 17 | H27: 42 | I27: 17 | J27: 59 | K27: =TRIM(IF(F27="No","Features ","")&IF(G27="","Weight ","")&IF(OR(H27="",I27="",J27="")," Dimensions","")) | L27: =IF(OR(G27="",H27="",I27="",J27=""),"No data",IF(AND(G27<=22,MAX(H27:J27)<=105,(H27*I27*J27)/1000000<=0.25),"Yes","Too big")) | M27: /product/core-trainer-landmine-with-t-bar-handle
A28: MBCTMA01 | B28: Abdominal Mat | C28: Body Weight | D28: Yes | F28: Yes | G28: 1 | H28: 38 | I28: 30 | J28: 6 | K28: =TRIM(IF(F28="No","Features ","")&IF(G28="","Weight ","")&IF(OR(H28="",I28="",J28="")," Dimensions","")) | L28: =IF(OR(G28="",H28="",I28="",J28=""),"No data",IF(AND(G28<=22,MAX(H28:J28)<=105,(H28*I28*J28)/1000000<=0.25),"Yes","Too big")) | M28: /product/abdominal-mat
A29: MBCTWH01 | B29: Abdominal Wheel | C29: Body Weight | D29: Yes | F29: No | G29: 3 | H29: 26 | I29: 20 | J29: 9.5 | K29: =TRIM(IF(F29="No","Features ","")&IF(G29="","Weight ","")&IF(OR(H29="",I29="",J29="")," Dimensions","")) | L29: =IF(OR(G29="",H29="",I29="",J29=""),"No data",IF(AND(G29<=22,MAX(H29:J29)<=105,(H29*I29*J29)/1000000<=0.25),"Yes","Too big")) | M29: /product/abdominal-wheel
A30: MBEMMA01 | B30: EVA Exercise Mat | C30: Body Weight | D30: Yes | F30: No | G30: 3 | H30: 140 | I30: 62 | J30: 1.6 | K30: =TRIM(IF(F30="No","Features ","")&IF(G30="","Weight ","")&IF(OR(H30="",I30="",J30="")," Dimensions","")) | L30: =IF(OR(G30="",H30="",I30="",J30=""),"No data",IF(AND(G30<=22,MAX(H30:J30)<=105,(H30*I30*J30)/1000000<=0.25),"Yes","Too big")) | M30: /product/eva-exercise-mat-2
A31: MBGYRI01 | B31: Gymnastic Rings (Wooden) | C31: Body Weight | D31: Yes | F31: Yes | G31: 2 | H31: 26 | I31: 26 | J31: 7 | K31: =TRIM(IF(F31="No","Features ","")&IF(G31="","Weight ","")&IF(OR(H31="",I31="",J31="")," Dimensions","")) | L31: =IF(OR(G31="",H31="",I31="",J31=""),"No data",IF(AND(G31<=22,MAX(H31:J31)<=105,(H31*I31*J31)/1000000<=0.25),"Yes","Too big")) | M31: /product/gymnastic-rings-wooden-2
... A54: MCRWAR03 | B54: Air Rower Elite | C54: Cardio | D54: Yes | F54: Yes | G54: 51 | H54: 146 | I54: 66 | J54: 38 | K54: =TRIM(IF(F54="No","Features ","")&IF(G54="","Weight ","")&IF(OR(H54="",I54="",J54="")," Dimensions","")) | L54: =IF(OR(G54="",H54="",I54="",J54=""),"No data",IF(AND(G54<=22,MAX(H54:J54)<=105,(H54*I54*J54)/1000000<=0.25),"Yes","Too big")) | M54: /product/air-rower-elite
A55: MCSTACC01 | B55: Ski Trainer Floor Stand | C55: Cardio | D55: Yes | F55: Yes | K55: =TRIM(IF(F55="No","Features ","")&IF(G55="","Weight ","")&IF(OR(H55="",I55="",J55="")," Dimensions","")) | L55: =IF(OR(G55="",H55="",I55="",J55=""),"No data",IF(AND(G55<=22,MAX(H55:J55)<=105,(H55*I55*J55)/1000000<=0.25),"Yes","Too big")) | M55: /product/ski-trainer-floor-stand-2
A56: MCSTACC02 | B56: Ski Trainer Wall Mount Bracket | C56: Cardio | D56: Yes | F56: Yes | G56: 2 | H56: 25 | I56: 12.5 | J56: 5 | K56: =TRIM(IF(F56="No","Features ","")&IF(G56="","Weight ","")&IF(OR(H56="",I56="",J56="")," Dimensions","")) | L56: =IF(OR(G56="",H56="",I56="",J56=""),"No data",IF(AND(G56<=22,MAX(H56:J56)<=105,(H56*I56*J56)/1000000<=0.25),"Yes","Too big")) | M56: /product/ski-trainer-wall-mount-bracket-2
A57: MCSTAR01 | B57: Ski Trainer Pro | C57: Cardio | D57: Yes | F57: Yes | G57: 49 | H57: 118 | I57: 61 | J57: 47 | K57: =TRIM(IF(F57="No","Features ","")&IF(G57="","Weight ","")&IF(OR(H57="",I57="",J57="")," Dimensions","")) | L57: =IF(OR(G57="",H57="",I57="",J57=""),"No data",IF(AND(G57<=22,MAX(H57:J57)<=105,(H57*I57*J57)/1000000<=0.25),"Yes","Too big")) | M57: /product/ski-trainer-pro
A58: MCSTAR02 | B58: Ski Trainer Elite | C58: Cardio | D58: Yes | F58: Yes | G58: 53 | H58: 118 | I58: 61 | J58: 47 | K58: =TRIM(IF(F58="No","Features ","")&IF(G58="","Weight ","")&IF(OR(H58="",I58="",J58="")," Dimensions","")) | L58: =IF(OR(G58="",H58="",I58="",J58=""),"No data",IF(AND(G58<=22,MAX(H58:J58)<=105,(H58*I58*J58)/1000000<=0.25),"Yes","Too big")) | M58: /product/ski-trainer-elite
A59: MCTMSP01 | B59: Curved Treadmill Pro | C59: Cardio | D59: Yes | F59: Yes | G59: 180 | H59: 185 | I59: 91 | J59: 56 | K59: =TRIM(IF(F59="No","Features ","")&IF(G59="","Weight ","")&IF(OR(H59="",I59="",J59="")," Dimensions","")) | L59: =IF(OR(G59="",H59="",I59="",J59=""),"No data",IF(AND(G59<=22,MAX(H59:J59)<=105,(H59*I59*J59)/1000000<=0.25),"Yes","Too big")) | M59: /product/curved-treadmill-pro
A60: MCTMSP02 | B60: Curved Treadmill Elite | C60: Cardio | D60: Yes | F60: Yes | G60: 601 | H60: 185 | I60: 91 | J60: 56 | K60: =TRIM(IF(F60="No","Features ","")&IF(G60="","Weight ","")&IF(OR(H60="",I60="",J60="")," Dimensions","")) | L60: =IF(OR(G60="",H60="",I60="",J60=""),"No data",IF(AND(G60<=22,MAX(H60:J60)<=105,(H60*I60*J60)/1000000<=0.25),"Yes","Too big")) | M60: /product/curved-treadmill-elite-2
A61: SCSTACC04 | B61: C2 Ski Erg Floor Stand | C61: Cardio | D61: Yes | F61: Yes | G61: 17 | H61: 1350 | I61: 660 | K61: =TRIM(IF(F61="No","Features ","")&IF(G61="","Weight ","")&IF(OR(H61="",I61="",J61="")," Dimensions","")) | L61: =IF(OR(G61="",H61="",I61="",J61=""),"No data",IF(AND(G61<=22,MAX(H61:J61)<=105,(H61*I61*J61)/1000000<=0.25),"Yes","Too big")) | M61: /product/c2-ski-erg-floor-stand
A62: SCSTAR03 | B62: C2 Ski Erg PM5 | C62: Cardio | D62: Yes | F62: Yes | G62: 27.5 | H62: 600 | I62: 1270 | K62: =TRIM(IF(F62="No","Features ","")&IF(G62="","Weight ","")&IF(OR(H62="",I62="",J62="")," Dimensions","")) | L62: =IF(OR(G62="",H62="",I62="",J62=""),"No data",IF(AND(G62<=22,MAX(H62:J62)<=105,(H62*I62*J62)/1000000<=0.25),"Yes","Too big")) | M62: /product/c2-ski-erg-pm5
...
